Workbook
Name lecid: #REF!
Name units: #REF!

Sheet task 2.5
A1: lec num | B1: units | C1: log units | D1: dummy | E1: duration | F1: First week sales | G1: Days left | H1: Predicted by model near-source | I1: Predicted by model out-source | K1: Simulation № | L1: Simulated demand | M1: Simulated demand in 1st week | N1: Average sim. Demand | O1: =ROUNDUP(AVERAGE(L2:L1001),0) -> 347 | R1: based on historical data
A2: 1 | B2: 173 | C2: =LOG10(B2) -> 2.2380461 | D2: 0 | E2: 21 | F2: 93 | G2: 14 | H2: =ROUNDUP(10^(MultiLogRegr2!$B$17 + D2*MultiLogRegr2!$B$18 + E2*MultiLogRegr2!$B$19 + MultiLogRegr2!$B$20*F2),0) -> 245 | I2: =ROUNDUP(10^(MultLogRegr1!$B$17+MultLogRegr1!$B$19*'task 2.5'!E2+MultLogRegr1!$B$18*'task 2.5'!D2),0) -> 316 | K2: 1 | L2: =_xlfn.NORM.INV(RAND(),$S$3,$S$2) -> 372.20066 | M2: =IF(L2<=0,0,10^(MultiLogRegr1stWeek!$B$17+LOG10(L2)*MultiLogRegr1stWeek!$B$18+MultiLogRegr1stWeek!$B$19*14+MultiLogRegr1stWeek!$B$20*0)) -> 167.74353 | N2: Average sim. 1st week demand | O2: =ROUNDUP(AVERAGE(M2:M1001),0) -> 167 | R2: sd | S2: 294.63997 | U2: simulation № | V2: Simulated demand | W2: Simulated demand in 1st week
A3: 2 | B3: 196 | C3: =LOG10(B3) -> 2.2922561 | D3: 0 | E3: 21 | F3: 108 | G3: 14 | H3: =ROUNDUP(10^(MultiLogRegr2!$B$17 + D3*MultiLogRegr2!$B$18 + E3*MultiLogRegr2!$B$19 + MultiLogRegr2!$B$20*F3),0) -> 266 | I3: =ROUNDUP(10^(MultLogRegr1!$B$17+MultLogRegr1!$B$19*'task 2.5'!E3+MultLogRegr1!$B$18*'task 2.5'!D3),0) -> 316 | K3: 2 | L3: =_xlfn.NORM.INV(RAND(),$S$3,$S$2) -> 624.36634 | M3: =IF(L3<=0,0,10^(MultiLogRegr1stWeek!$B$17+LOG10(L3)*MultiLogRegr1stWeek!$B$18+MultiLogRegr1stWeek!$B$19*14+MultiLogRegr1stWeek!$B$20*0)) -> 284.48034 | R3: mean | S3: 337.56522 | U3: 1 | V3: =O1 -> 347 | W3: =O2 -> 167
A4: 3 | B4: 195 | C4: =LOG10(B4) -> 2.2900346 | D4: 0 | E4: 13 | F4: 155 | G4: 6 | H4: =ROUNDUP(10^(MultiLogRegr2!$B$17 + D4*MultiLogRegr2!$B$18 + E4*MultiLogRegr2!$B$19 + MultiLogRegr2!$B$20*F4),0) -> 222 | I4: =ROUNDUP(10^(MultLogRegr1!$B$17+MultLogRegr1!$B$19*'task 2.5'!E4+MultLogRegr1!$B$18*'task 2.5'!D4),0) -> 185 | K4: 3 | L4: =_xlfn.NORM.INV(RAND(),$S$3,$S$2) -> 163.25287 | M4: =IF(L4<=0,0,10^(MultiLogRegr1stWeek!$B$17+LOG10(L4)*MultiLogRegr1stWeek!$B$18+MultiLogRegr1stWeek!$B$19*14+MultiLogRegr1stWeek!$B$20*0)) -> 72.305523 | U4: 2 | V4: 343 | W4: 162
A5: 4 | B5: 210 | C5: =LOG10(B5) -> 2.3222193 | D5: 0 | E5: 15 | F5: 103 | G5: 8 | H5: =ROUNDUP(10^(MultiLogRegr2!$B$17 + D5*MultiLogRegr2!$B$18 + E5*MultiLogRegr2!$B$19 + MultiLogRegr2!$B$20*F5),0) -> 187 | I5: =ROUNDUP(10^(MultLogRegr1!$B$17+MultLogRegr1!$B$19*'task 2.5'!E5+MultLogRegr1!$B$18*'task 2.5'!D5),0) -> 211 | K5: 4 | L5: =_xlfn.NORM.INV(RAND(),$S$3,$S$2) -> 661.89777 | M5: =IF(L5<=0,0,10^(MultiLogRegr1stWeek!$B$17+LOG10(L5)*MultiLogRegr1stWeek!$B$18+MultiLogRegr1stWeek!$B$19*14+MultiLogRegr1stWeek!$B$20*0)) -> 301.95277 | U5: 3 | V5: 343 | W5: 164
A6: 5 | B6: 291 | C6: =LOG10(B6) -> 2.463893 | D6: 0 | E6: 13 | F6: 208 | G6: 6 | H6: =ROUNDUP(10^(MultiLogRegr2!$B$17 + D6*MultiLogRegr2!$B$18 + E6*MultiLogRegr2!$B$19 + MultiLogRegr2!$B$20*F6),0) -> 295 | I6: =ROUNDUP(10^(MultLogRegr1!$B$17+MultLogRegr1!$B$19*'task 2.5'!E6+MultLogRegr1!$B$18*'task 2.5'!D6),0) -> 185 | K6: 5 | L6: =_xlfn.NORM.INV(RAND(),$S$3,$S$2) -> 508.52925 | M6: =IF(L6<=0,0,10^(MultiLogRegr1stWeek!$B$17+LOG10(L6)*MultiLogRegr1stWeek!$B$18+MultiLogRegr1stWeek!$B$19*14+MultiLogRegr1stWeek!$B$20*0)) -> 230.69953 | U6: 4 | V6: 344 | W6: 164
A7: 6 | B7: 170 | C7: =LOG10(B7) -> 2.2304489 | D7: 0 | E7: 14 | F7: 103 | G7: 7 | H7: =ROUNDUP(10^(MultiLogRegr2!$B$17 + D7*MultiLogRegr2!$B$18 + E7*MultiLogRegr2!$B$19 + MultiLogRegr2!$B$20*F7),0) -> 177 | I7: =ROUNDUP(10^(MultLogRegr1!$B$17+MultLogRegr1!$B$19*'task 2.5'!E7+MultLogRegr1!$B$18*'task 2.5'!D7),0) -> 198 | K7: 6 | L7: =_xlfn.NORM.INV(RAND(),$S$3,$S$2) -> 141.16656 | M7: =IF(L7<=0,0,10^(MultiLogRegr1stWeek!$B$17+LOG10(L7)*MultiLogRegr1stWeek!$B$18+MultiLogRegr1stWeek!$B$19*14+MultiLogRegr1stWeek!$B$20*0)) -> 62.33176 | U7: 5 | V7: 330 | W7: 158
A8: 7 | B8: 252 | C8: =LOG10(B8) -> 2.4014005 | D8: 0 | E8: 15 | F8: 163 | G8: 8 | H8: =ROUNDUP(10^(MultiLogRegr2!$B$17 + D8*MultiLogRegr2!$B$18 + E8*MultiLogRegr2!$B$19 + MultiLogRegr2!$B$20*F8),0) -> 258 | I8: =ROUNDUP(10^(MultLogRegr1!$B$17+MultLogRegr1!$B$19*'task 2.5'!E8+MultLogRegr1!$B$18*'task 2.5'!D8),0) -> 211 | K8: 7 | L8: =_xlfn.NORM.INV(RAND(),$S$3,$S$2) -> -165.97439 | M8: =IF(L8<=0,0,10^(MultiLogRegr1stWeek!$B$17+LOG10(L8)*MultiLogRegr1stWeek!$B$18+MultiLogRegr1stWeek!$B$19*14+MultiLogRegr1stWeek!$B$20*0)) -> 0 | U8: 6 | V8: 339 | W8: 163
A9: 8 | B9: 520 | C9: =LOG10(B9) -> 2.7160033 | D9: 0 | E9: 21 | F9: 272 | G9: 14 | H9: =ROUNDUP(10^(MultiLogRegr2!$B$17 + D9*MultiLogRegr2!$B$18 + E9*MultiLogRegr2!$B$19 + MultiLogRegr2!$B$20*F9),0) -> 642 | I9: =ROUNDUP(10^(MultLogRegr1!$B$17+MultLogRegr1!$B$19*'task 2.5'!E9+MultLogRegr1!$B$18*'task 2.5'!D9),0) -> 316 | K9: 8 | L9: =_xlfn.NORM.INV(RAND(),$S$3,$S$2) -> 435.63328 | M9: =IF(L9<=0,0,10^(MultiLogRegr1stWeek!$B$17+LOG10(L9)*MultiLogRegr1stWeek!$B$18+MultiLogRegr1stWeek!$B$19*14+MultiLogRegr1stWeek!$B$20*0)) -> 196.98488 | U9: 7 | V9: 336 | W9: 162
A10: 9 | B10: 164 | C10: =LOG10(B10) -> 2.2148438 | D10: 0 | E10: 14 | F10: 83 | G10: 7 | H10: =ROUNDUP(10^(MultiLogRegr2!$B$17 + D10*MultiLogRegr2!$B$18 + E10*MultiLogRegr2!$B$19 + MultiLogRegr2!$B$20*F10),0) -> 159 | I10: =ROUNDUP(10^(MultLogRegr1!$B$17+MultLogRegr1!$B$19*'task 2.5'!E10+MultLogRegr1!$B$18*'task 2.5'!D10),0) -> 198 | K10: 9 | L10: =_xlfn.NORM.INV(RAND(),$S$3,$S$2) -> 192.79487 | M10: =IF(L10<=0,0,10^(MultiLogRegr1stWeek!$B$17+LOG10(L10)*MultiLogRegr1stWeek!$B$18+MultiLogRegr1stWeek!$B$19*14+MultiLogRegr1stWeek!$B$20*0)) -> 85.69026 | U10: 8 | V10: 338 | W10: 162
A11: 10 | B11: 135 | C11: =LOG10(B11) -> 2.1303338 | D11: 0 | E11: 14 | F11: 91 | G11: 7 | H11: =ROUNDUP(10^(MultiLogRegr2!$B$17 + D11*MultiLogRegr2!$B$18 + E11*MultiLogRegr2!$B$19 + MultiLogRegr2!$B$20*F11),0) -> 166 | I11: =ROUNDUP(10^(MultLogRegr1!$B$17+MultLogRegr1!$B$19*'task 2.5'!E11+MultLogRegr1!$B$18*'task 2.5'!D11),0) -> 198 | K11: 10 | L11: =_xlfn.NORM.INV(RAND(),$S$3,$S$2) -> 942.03214 | M11: =IF(L11<=0,0,10^(MultiLogRegr1stWeek!$B$17+LOG10(L11)*MultiLogRegr1stWeek!$B$18+MultiLogRegr1stWeek!$B$19*14+MultiLogRegr1stWeek!$B$20*0)) -> 432.9627 | U11: 9 | V11: 329 | W11: 158
A12: 11 | B12: 153 | C12: =LOG10(B12) -> 2.1846914 | D12: 0 | E12: 14 | F12: 79 | G12: 7 | H12: =ROUNDUP(10^(MultiLogRegr2!$B$17 + D12*MultiLogRegr2!$B$18 + E12*MultiLogRegr2!$B$19 + MultiLogRegr2!$B$20*F12),0) -> 155 | I12: =ROUNDUP(10^(MultLogRegr1!$B$17+MultLogRegr1!$B$19*'task 2.5'!E12+MultLogRegr1!$B$18*'task 2.5'!D12),0) -> 198 | K12: 11 | L12: =_xlfn.NORM.INV(RAND(),$S$3,$S$2) -> 273.07585 | M12: =IF(L12<=0,0,10^(MultiLogRegr1stWeek!$B$17+LOG10(L12)*MultiLogRegr1stWeek!$B$18+MultiLogRegr1stWeek!$B$19*14+MultiLogRegr1stWeek!$B$20*0)) -> 122.26774 | U12: 10 | V12: 343 | W12: 166
A13: 12 | B13: 322 | C13: =LOG10(B13) -> 2.5078559 | D13: 0 | E13: 16 | F13: 116 | G13: 9 | H13: =ROUNDUP(10^(MultiLogRegr2!$B$17 + D13*MultiLogRegr2!$B$18 + E13*MultiLogRegr2!$B$19 + MultiLogRegr2!$B$20*F13),0) -> 211 | I13: =ROUNDUP(10^(MultLogRegr1!$B$17+MultLogRegr1!$B$19*'task 2.5'!E13+MultLogRegr1!$B$18*'task 2.5'!D13),0) -> 226 | K13: 12 | L13: =_xlfn.NORM.INV(RAND(),$S$3,$S$2) -> 731.60287 | M13: =IF(L13<=0,0,10^(MultiLogRegr1stWeek!$B$17+LOG10(L13)*MultiLogRegr1stWeek!$B$18+MultiLogRegr1stWeek!$B$19*14+MultiLogRegr1stWeek!$B$20*0)) -> 334.45813 | U13: 11 | V13: 338 | W13: 161
A14: 13 | B14: 298 | C14: =LOG10(B14) -> 2.4742163 | D14: 0 | E14: 26 | F14: 120 | G14: 19 | H14: =ROUNDUP(10^(MultiLogRegr2!$B$17 + D14*MultiLogRegr2!$B$18 + E14*MultiLogRegr2!$B$19 + MultiLogRegr2!$B$20*F14),0) -> 372 | I14: =ROUNDUP(10^(MultLogRegr1!$B$17+MultLogRegr1!$B$19*'task 2.5'!E14+MultLogRegr1!$B$18*'task 2.5'!D14),0) -> 442 | K14: 13 | L14: =_xlfn.NORM.INV(RAND(),$S$3,$S$2) -> 1220.764 | M14: =IF(L14<=0,0,10^(MultiLogRegr1stWeek!$B$17+LOG10(L14)*MultiLogRegr1stWeek!$B$18+MultiLogRegr1stWeek!$B$19*14+MultiLogRegr1stWeek!$B$20*0)) -> 564.14856 | U14: 12 | V14: 319 | W14: 155
A15: 14 | B15: 133 | C15: =LOG10(B15) -> 2.1238516 | D15: 0 | E15: 16 | F15: 49 | G15: 9 | H15: =ROUNDUP(10^(MultiLogRegr2!$B$17 + D15*MultiLogRegr2!$B$18 + E15*MultiLogRegr2!$B$19 + MultiLogRegr2!$B$20*F15),0) -> 147 | I15: =ROUNDUP(10^(MultLogRegr1!$B$17+MultLogRegr1!$B$19*'task 2.5'!E15+MultLogRegr1!$B$18*'task 2.5'!D15),0) -> 226 | K15: 14 | L15: =_xlfn.NORM.INV(RAND(),$S$3,$S$2) -> 243.66934 | M15: =IF(L15<=0,0,10^(MultiLogRegr1stWeek!$B$17+LOG10(L15)*MultiLogRegr1stWeek!$B$18+MultiLogRegr1stWeek!$B$19*14+MultiLogRegr1stWeek!$B$20*0)) -> 108.83901 | U15: 13 | V15: 353 | W15: 167
... A24: 23 | B24: 385 | C24: =LOG10(B24) -> 2.5854607 | D24: 0 | E24: 13 | F24: 171 | G24: 6 | H24: =ROUNDUP(10^(MultiLogRegr2!$B$17 + D24*MultiLogRegr2!$B$18 + E24*MultiLogRegr2!$B$19 + MultiLogRegr2!$B$20*F24),0) -> 241 | I24: =ROUNDUP(10^(MultLogRegr1!$B$17+MultLogRegr1!$B$19*'task 2.5'!E24+MultLogRegr1!$B$18*'task 2.5'!D24),0) -> 185 | K24: 23 | L24: =_xlfn.NORM.INV(RAND(),$S$3,$S$2) -> 276.03486 | M24: =IF(L24<=0,0,10^(MultiLogRegr1stWeek!$B$17+LOG10(L24)*MultiLogRegr1stWeek!$B$18+MultiLogRegr1stWeek!$B$19*14+MultiLogRegr1stWeek!$B$20*0)) -> 123.62074 | U24: 22 | V24: 332 | W24: 159
A25: 24 | B25: =ROUNDUP(AVERAGE(V3:V1002),0) -> 339 | C25: =LOG10(B25) -> 2.5301997 | D25: 0 | E25: 21 | F25: =ROUNDUP(AVERAGE(W3:W1002),0) -> 162 | G25: 14 | H25: =ROUNDUP(10^(MultiLogRegr2!$B$17 + D25*MultiLogRegr2!$B$18 + E25*MultiLogRegr2!$B$19 + MultiLogRegr2!$B$20*F25),0) -> 355 | I25: =ROUNDUP(10^(MultLogRegr1!$B$17+MultLogRegr1!$B$19*'task 2.5'!E25+MultLogRegr1!$B$18*'task 2.5'!D25),0) -> 316 | K25: 24 | L25: =_xlfn.NORM.INV(RAND(),$S$3,$S$2) -> 74.733107 | M25: =IF(L25<=0,0,10^(MultiLogRegr1stWeek!$B$17+LOG10(L25)*MultiLogRegr1stWeek!$B$18+MultiLogRegr1stWeek!$B$19*14+MultiLogRegr1stWeek!$B$20*0)) -> 32.558004 | U25: 23 | V25: 339 | W25: 162
H26: Num. of shirts to order locally: | I26: =MAX(H25-I25,0) -> 39 | K26: 25 | L26: =_xlfn.NORM.INV(RAND(),$S$3,$S$2) -> 648.05336 | M26: =IF(L26<=0,0,10^(MultiLogRegr1stWeek!$B$17+LOG10(L26)*MultiLogRegr1stWeek!$B$18+MultiLogRegr1stWeek!$B$19*14+MultiLogRegr1stWeek!$B$20*0)) -> 295.50513 | U26: 24 | V26: 335 | W26: 161
K27: 26 | L27: =_xlfn.NORM.INV(RAND(),$S$3,$S$2) -> 448.55817 | M27: =IF(L27<=0,0,10^(MultiLogRegr1stWeek!$B$17+LOG10(L27)*MultiLogRegr1stWeek!$B$18+MultiLogRegr1stWeek!$B$19*14+MultiLogRegr1stWeek!$B$20*0)) -> 202.95453 | U27: 25 | V27: 344 | W27: 165
K28: 27 | L28: =_xlfn.NORM.INV(RAND(),$S$3,$S$2) -> 992.22314 | M28: =IF(L28<=0,0,10^(MultiLogRegr1stWeek!$B$17+LOG10(L28)*MultiLogRegr1stWeek!$B$18+MultiLogRegr1stWeek!$B$19*14+MultiLogRegr1stWeek!$B$20*0)) -> 456.53088 | U28: 26 | V28: 324 | W28: 158
K29: 28 | L29: =_xlfn.NORM.INV(RAND(),$S$3,$S$2) -> -42.125023 | M29: =IF(L29<=0,0,10^(MultiLogRegr1stWeek!$B$17+LOG10(L29)*MultiLogRegr1stWeek!$B$18+MultiLogRegr1stWeek!$B$19*14+MultiLogRegr1stWeek!$B$20*0)) -> 0 | U29: 27 | V29: 336 | W29: 162
A30: lec num | B30: First week sales | C30: Log 1st week | D30: log units | E30: Days left | F30: dummy | K30: 29 | L30: =_xlfn.NORM.INV(RAND(),$S$3,$S$2) -> -34.662949 | M30: =IF(L30<=0,0,10^(MultiLogRegr1stWeek!$B$17+LOG10(L30)*MultiLogRegr1stWeek!$B$18+MultiLogRegr1stWeek!$B$19*14+MultiLogRegr1stWeek!$B$20*0)) -> 0 | U30: 28 | V30: 331 | W30: 158
A31: 1 | B31: 93 | C31: =LOG10(B31) -> 1.9684829 | D31: 2.2380461 | E31: 14 | F31: 0 | K31: 30 | L31: =_xlfn.NORM.INV(RAND(),$S$3,$S$2) -> -11.665938 | M31: =IF(L31<=0,0,10^(MultiLogRegr1stWeek!$B$17+LOG10(L31)*MultiLogRegr1stWeek!$B$18+MultiLogRegr1stWeek!$B$19*14+MultiLogRegr1stWeek!$B$20*0)) -> 0 | U31: 29 | V31: 337 | W31: 161
A32: 2 | B32: 108 | C32: =LOG10(B32) -> 2.0334238 | D32: 2.2922561 | E32: 14 | F32: 0 | K32: 31 | L32: =_xlfn.NORM.INV(RAND(),$S$3,$S$2) -> 446.04228 | M32: =IF(L32<=0,0,10^(MultiLogRegr1stWeek!$B$17+LOG10(L32)*MultiLogRegr1stWeek!$B$18+MultiLogRegr1stWeek!$B$19*14+MultiLogRegr1stWeek!$B$20*0)) -> 201.79222 | U32: 30 | V32: 334 | W32: 161
A33: 3 | B33: 155 | C33: =LOG10(B33) -> 2.1903317 | D33: 2.2900346 | E33: 6 | F33: 0 | K33: 32 | L33: =_xlfn.NORM.INV(RAND(),$S$3,$S$2) -> 860.26231 | M33: =IF(L33<=0,0,10^(MultiLogRegr1stWeek!$B$17+LOG10(L33)*MultiLogRegr1stWeek!$B$18+MultiLogRegr1stWeek!$B$19*14+MultiLogRegr1stWeek!$B$20*0)) -> 394.62348 | U33: 31 | V33: 350 | W33: 166
A34: 4 | B34: 103 | C34: =LOG10(B34) -> 2.0128372 | D34: 2.3222193 | E34: 8 | F34: 0 | K34: 33 | L34: =_xlfn.NORM.INV(RAND(),$S$3,$S$2) -> 286.65622 | M34: =IF(L34<=0,0,10^(MultiLogRegr1stWeek!$B$17+LOG10(L34)*MultiLogRegr1stWeek!$B$18+MultiLogRegr1stWeek!$B$19*14+MultiLogRegr1stWeek!$B$20*0)) -> 128.47986 | U34: 32 | V34: 357 | W34: 169
A35: 5 | B35: 208 | C35: =LOG10(B35) -> 2.3180633 | D35: 2.463893 | E35: 6 | F35: 0 | K35: 34 | L35: =_xlfn.NORM.INV(RAND(),$S$3,$S$2) -> 697.35955 | M35: =IF(L35<=0,0,10^(MultiLogRegr1stWeek!$B$17+LOG10(L35)*MultiLogRegr1stWeek!$B$18+MultiLogRegr1stWeek!$B$19*14+MultiLogRegr1stWeek!$B$20*0)) -> 318.48097 | U35: 33 | V35: 347 | W35: 165
A36: 6 | B36: 103 | C36: =LOG10(B36) -> 2.0128372 | D36: 2.2304489 | E36: 7 | F36: 0 | K36: 35 | L36: =_xlfn.NORM.INV(RAND(),$S$3,$S$2) -> -260.632 | M36: =IF(L36<=0,0,10^(MultiLogRegr1stWeek!$B$17+LOG10(L36)*MultiLogRegr1stWeek!$B$18+MultiLogRegr1stWeek!$B$19*14+MultiLogRegr1stWeek!$B$20*0)) -> 0 | U36: 34 | V36: 340 | W36: 165
A37: 7 | B37: 163 | C37: =LOG10(B37) -> 2.2121876 | D37: 2.4014005 | E37: 8 | F37: 0 | K37: 36 | L37: =_xlfn.NORM.INV(RAND(),$S$3,$S$2) -> -357.96659 | M37: =IF(L37<=0,0,10^(MultiLogRegr1stWeek!$B$17+LOG10(L37)*MultiLogRegr1stWeek!$B$18+MultiLogRegr1stWeek!$B$19*14+MultiLogRegr1stWeek!$B$20*0)) -> 0 | U37: 35 | V37: 322 | W37: 155
A38: 8 | B38: 272 | C38: =LOG10(B38) -> 2.4345689 | D38: 2.7160033 | E38: 14 | F38: 0 | K38: 37 | L38: =_xlfn.NORM.INV(RAND(),$S$3,$S$2) -> 253.03287 | M38: =IF(L38<=0,0,10^(MultiLogRegr1stWeek!$B$17+LOG10(L38)*MultiLogRegr1stWeek!$B$18+MultiLogRegr1stWeek!$B$19*14+MultiLogRegr1stWeek!$B$20*0)) -> 113.11141 | U38: 36 | V38: 334 | W38: 162
A39: 9 | B39: 83 | C39: =LOG10(B39) -> 1.9190781 | D39: 2.2148438 | E39: 7 | F39: 0 | K39: 38 | L39: =_xlfn.NORM.INV(RAND(),$S$3,$S$2) -> 255.18056 | M39: =IF(L39<=0,0,10^(MultiLogRegr1stWeek!$B$17+LOG10(L39)*MultiLogRegr1stWeek!$B$18+MultiLogRegr1stWeek!$B$19*14+MultiLogRegr1stWeek!$B$20*0)) -> 114.09184 | U39: 37 | V39: 335 | W39: 161
A40: 10 | B40: 91 | C40: =LOG10(B40) -> 1.9590414 | D40: 2.1303338 | E40: 7 | F40: 0 | K40: 39 | L40: =_xlfn.NORM.INV(RAND(),$S$3,$S$2) -> 368.16051 | M40: =IF(L40<=0,0,10^(MultiLogRegr1stWeek!$B$17+LOG10(L40)*MultiLogRegr1stWeek!$B$18+MultiLogRegr1stWeek!$B$19*14+MultiLogRegr1stWeek!$B$20*0)) -> 165.88448 | U40: 38 | V40: 328 | W40: 158
A41: 11 | B41: 79 | C41: =LOG10(B41) -> 1.8976271 | D41: 2.1846914 | E41: 7 | F41: 0 | K41: 40 | L41: =_xlfn.NORM.INV(RAND(),$S$3,$S$2) -> 264.74081 | M41: =IF(L41<=0,0,10^(MultiLogRegr1stWeek!$B$17+LOG10(L41)*MultiLogRegr1stWeek!$B$18+MultiLogRegr1stWeek!$B$19*14+MultiLogRegr1stWeek!$B$20*0)) -> 118.45822 | U41: 39 | V41: 313 | W41: 151
A42: 12 | B42: 116 | C42: =LOG10(B42) -> 2.064458 | D42: 2.5078559 | E42: 9 | F42: 0 | K42: 41 | L42: =_xlfn.NORM.INV(RAND(),$S$3,$S$2) -> 335.58799 | M42: =IF(L42<=0,0,10^(MultiLogRegr1stWeek!$B$17+LOG10(L42)*MultiLogRegr1stWeek!$B$18+MultiLogRegr1stWeek!$B$19*14+MultiLogRegr1stWeek!$B$20*0)) -> 150.91257 | U42: 40 | V42: 335 | W42: 160
... A53: 23 | B53: 171 | C53: =LOG10(B53) -> 2.2329961 | D53: 2.5854607 | E53: 6 | F53: 1 | K53: 52 | L53: =_xlfn.NORM.INV(RAND(),$S$3,$S$2) -> 586.14983 | M53: =IF(L53<=0,0,10^(MultiLogRegr1stWeek!$B$17+LOG10(L53)*MultiLogRegr1stWeek!$B$18+MultiLogRegr1stWeek!$B$19*14+MultiLogRegr1stWeek!$B$20*0)) -> 266.71176 | U53: 51 | V53: 339 | W53: 163
K54: 53 | L54: =_xlfn.NORM.INV(RAND(),$S$3,$S$2) -> 731.6867 | M54: =IF(L54<=0,0,10^(MultiLogRegr1stWeek!$B$17+LOG10(L54)*MultiLogRegr1stWeek!$B$18+MultiLogRegr1stWeek!$B$19*14+MultiLogRegr1stWeek!$B$20*0)) -> 334.49726 | U54: 52 | V54: 342 | W54: 165
K55: 54 | L55: =_xlfn.NORM.INV(RAND(),$S$3,$S$2) -> 309.38503 | M55: =IF(L55<=0,0,10^(MultiLogRegr1stWeek!$B$17+LOG10(L55)*MultiLogRegr1stWeek!$B$18+MultiLogRegr1stWeek!$B$19*14+MultiLogRegr1stWeek!$B$20*0)) -> 138.89056 | U55: 53 | V55: 327 | W55: 156
K56: 55 | L56: =_xlfn.NORM.INV(RAND(),$S$3,$S$2) -> 78.175015 | M56: =IF(L56<=0,0,10^(MultiLogRegr1stWeek!$B$17+LOG10(L56)*MultiLogRegr1stWeek!$B$18+MultiLogRegr1stWeek!$B$19*14+MultiLogRegr1stWeek!$B$20*0)) -> 34.089894 | U56: 54 | V56: 346 | W56: 164
K57: 56 | L57: =_xlfn.NORM.INV(RAND(),$S$3,$S$2) -> 780.12436 | M57: =IF(L57<=0,0,10^(MultiLogRegr1stWeek!$B$17+LOG10(L57)*MultiLogRegr1stWeek!$B$18+MultiLogRegr1stWeek!$B$19*14+MultiLogRegr1stWeek!$B$20*0)) -> 357.12406 | U57: 55 | V57: 327 | W57: 158
K58: 57 | L58: =_xlfn.NORM.INV(RAND(),$S$3,$S$2) -> 796.65228 | M58: =IF(L58<=0,0,10^(MultiLogRegr1stWeek!$B$17+LOG10(L58)*MultiLogRegr1stWeek!$B$18+MultiLogRegr1stWeek!$B$19*14+MultiLogRegr1stWeek!$B$20*0)) -> 364.85167 | U58: 56 | V58: 338 | W58: 162
...

Sheet task 2.6
A1: lec num | B1: units sold | C1: Predicted by model near-source | D1: Predicted by model out-source | E1: Days left after 1st week | F1: 1st week sales | H1: Shirts order (before 1st week) | I1: left in inventory after 1st week | J1: Shirts needed locally (after 1st week) | K1: Maximum production locally | L1: Shirts order locally | M1: Revenue near | N1: Cost near | O1: Profit near | Q1: Revenue out | R1: Cost out | S1: Profit out
A2: 11 | B2: 153 | C2: 155 | D2: 198 | E2: 7 | F2: 91 | H2: 198 | I2: =MAX(H2-F2,0) -> 107 | J2: =MAX(C2-F2-I2,0) -> 0 | K2: =E2*$B$21 -> 84 | L2: =MIN(J2,K2) -> 0 | M2: =(H2+L2)*$B$18 -> 26730 | N2: =L2*$B$20+H2*$B$19 -> 12870 | O2: =M2-N2 -> 13860 | Q2: =MIN(D2)*$B$18 -> 26730 | R2: =D2*$B$19 -> 12870 | S2: =Q2-R2 -> 13860
A3: 12 | B3: 322 | C3: 211 | D3: 226 | E3: 7 | F3: 79 | H3: 226 | I3: =MAX(H3-F3,0) -> 147 | J3: =MAX(C3-F3-I3,0) -> 0 | K3: =E3*$B$21 -> 84 | L3: =MIN(J3,K3) -> 0 | M3: =(H3+L3)*$B$18 -> 30510 | N3: =L3*$B$20+H3*$B$19 -> 14690 | O3: =M3-N3 -> 15820 | Q3: =MIN(D3)*$B$18 -> 30510 | R3: =D3*$B$19 -> 14690 | S3: =Q3-R3 -> 15820
A4: 13 | B4: 298 | C4: 372 | D4: 442 | E4: 9 | F4: 116 | H4: 442 | I4: =MAX(H4-F4,0) -> 326 | J4: =MAX(C4-F4-I4,0) -> 0 | K4: =E4*$B$21 -> 108 | L4: =MIN(J4,K4) -> 0 | M4: =(H4+L4)*$B$18 -> 59670 | N4: =L4*$B$20+H4*$B$19 -> 28730 | O4: =M4-N4 -> 30940 | Q4: =MIN(D4)*$B$18 -> 59670 | R4: =D4*$B$19 -> 28730 | S4: =Q4-R4 -> 30940
A5: 14 | B5: 133 | C5: 147 | D5: 226 | E5: 19 | F5: 120 | H5: 226 | I5: =MAX(H5-F5,0) -> 106 | J5: =MAX(C5-F5-I5,0) -> 0 | K5: =E5*$B$21 -> 228 | L5: =MIN(J5,K5) -> 0 | M5: =(H5+L5)*$B$18 -> 30510 | N5: =L5*$B$20+H5*$B$19 -> 14690 | O5: =M5-N5 -> 15820 | Q5: =MIN(D5)*$B$18 -> 30510 | R5: =D5*$B$19 -> 14690 | S5: =Q5-R5 -> 15820
A6: 15 | B6: 192 | C6: 233 | D6: 258 | E6: 9 | F6: 49 | H6: 258 | I6: =MAX(H6-F6,0) -> 209 | J6: =MAX(C6-F6-I6,0) -> 0 | K6: =E6*$B$21 -> 108 | L6: =MIN(J6,K6) -> 0 | M6: =(H6+L6)*$B$18 -> 34830 | N6: =L6*$B$20+H6*$B$19 -> 16770 | O6: =M6-N6 -> 18060 | Q6: =MIN(D6)*$B$18 -> 34830 | R6: =D6*$B$19 -> 16770 | S6: =Q6-R6 -> 18060
A7: 16 | B7: 198 | C7: 156 | D7: 198 | E7: 11 | F7: 114 | H7: 198 | I7: =MAX(H7-F7,0) -> 84 | J7: =MAX(C7-F7-I7,0) -> 0 | K7: =E7*$B$21 -> 132 | L7: =MIN(J7,K7) -> 0 | M7: =(H7+L7)*$B$18 -> 26730 | N7: =L7*$B$20+H7*$B$19 -> 12870 | O7: =M7-N7 -> 13860 | Q7: =MIN(D7)*$B$18 -> 26730 | R7: =D7*$B$19 -> 12870 | S7: =Q7-R7 -> 13860
A8: 17 | B8: 991 | C8: 697 | D8: 863 | E8: 7 | F8: 80 | H8: 863 | I8: =MAX(H8-F8,0) -> 783 | J8: =MAX(C8-F8-I8,0) -> 0 | K8: =E8*$B$21 -> 84 | L8: =MIN(J8,K8) -> 0 | M8: =(H8+L8)*$B$18 -> 116505 | N8: =L8*$B$20+H8*$B$19 -> 56095 | O8: =M8-N8 -> 60410 | Q8: =MIN(D8)*$B$18 -> 116505 | R8: =D8*$B$19 -> 56095 | S8: =Q8-R8 -> 60410
A9: 18 | B9: 1244 | C9: 1244 | D9: 1244 | E9: 29 | F9: 136 | H9: 1244 | I9: =MAX(H9-F9,0) -> 1108 | J9: =MAX(C9-F9-I9,0) -> 0 | K9: =E9*$B$21 -> 348 | L9: =MIN(J9,K9) -> 0 | M9: =(H9+L9)*$B$18 -> 167940 | N9: =L9*$B$20+H9*$B$19 -> 80860 | O9: =M9-N9 -> 87080 | Q9: =MIN(D9)*$B$18 -> 167940 | R9: =D9*$B$19 -> 80860 | S9: =Q9-R9 -> 87080
A10: 19 | B10: 855 | C10: 757 | D10: 505 | E10: 28 | F10: 168 | H10: 505 | I10: =MAX(H10-F10,0) -> 337 | J10: =MAX(C10-F10-I10,0) -> 252 | K10: =E10*$B$21 -> 336 | L10: =MIN(J10,K10) -> 252 | M10: =(H10+L10)*$B$18 -> 102195 | N10: =L10*$B$20+H10*$B$19 -> 56765 | O10: =M10-N10 -> 45430 | Q10: =MIN(D10)*$B$18 -> 68175 | R10: =D10*$B$19 -> 32825 | S10: =Q10-R10 -> 35350
A11: 20 | B11: 291 | C11: 362 | D11: 242 | E11: 21 | F11: 232 | H11: 242 | I11: =MAX(H11-F11,0) -> 10 | J11: =MAX(C11-F11-I11,0) -> 120 | K11: =E11*$B$21 -> 252 | L11: =MIN(J11,K11) -> 120 | M11: =(H11+L11)*$B$18 -> 48870 | N11: =L11*$B$20+H11*$B$19 -> 27130 | O11: =M11-N11 -> 21740 | Q11: =MIN(D11)*$B$18 -> 32670 | R11: =D11*$B$19 -> 15730 | S11: =Q11-R11 -> 16940
A12: 21 | B12: 143 | C12: 151 | D12: 162 | E12: 10 | F12: 206 | H12: 162 | I12: =MAX(H12-F12,0) -> 0 | J12: =MAX(C12-F12-I12,0) -> 0 | K12: =E12*$B$21 -> 120 | L12: =MIN(J12,K12) -> 0 | M12: =(H12+L12)*$B$18 -> 21870 | N12: =L12*$B$20+H12*$B$19 -> 10530 | O12: =M12-N12 -> 11340 | Q12: =MIN(D12)*$B$18 -> 21870 | R12: =D12*$B$19 -> 10530 | S12: =Q12-R12 -> 11340
A13: 22 | B13: 253 | C13: 191 | D13: 198 | E13: 4 | F13: 104 | H13: 198 | I13: =MAX(H13-F13,0) -> 94 | J13: =MAX(C13-F13-I13,0) -> 0 | K13: =E13*$B$21 -> 48 | L13: =MIN(J13,K13) -> 0 | M13: =(H13+L13)*$B$18 -> 26730 | N13: =L13*$B$20+H13*$B$19 -> 12870 | O13: =M13-N13 -> 13860 | Q13: =MIN(D13)*$B$18 -> 26730 | R13: =D13*$B$19 -> 12870 | S13: =Q13-R13 -> 13860
... A15: 24 | B15: 338 | C15: 355 | D15: 316 | E15: 6 | F15: 171 | H15: 316 | I15: =MAX(H15-F15,0) -> 145 | J15: =MAX(C15-F15-I15,0) -> 39 | K15: =E15*$B$21 -> 72 | L15: =MIN(J15,K15) -> 39 | M15: =(H15+L15)*$B$18 -> 47925 | N15: =L15*$B$20+H15*$B$19 -> 24245 | O15: =M15-N15 -> 23680 | Q15: =MIN(D15)*$B$18 -> 42660 | R15: =D15*$B$19 -> 20540 | S15: =Q15-R15 -> 22120
N16: Total profit near: | O16: =SUM(O2:O15) -> 387090 | R16: Total profit: | S16: =SUM(S2:S15) -> 368410
A18: Price | B18: 135
A19: Cost Ukraine | B19: 65
A20: Cost locally | B20: 95
A21: Local capacity/day | B21: 12 | D21: So the near-sourcing model is more profitable by: | E21: =O16-S16 -> 18680

Sheet MultiLogRegr2
A1: SUMMARY OUTPUT
A3: Regression Statistics
A4: Multiple R | B4: 0.9324664
A5: R Square | B5: 0.86949359
A6: Adjusted R Square | B6: 0.84888731
A7: Standard Error | B7: 0.10689173
A8: Observations | B8: 23
A10: ANOVA
B11: df | C11: SS | D11: MS | E11: F | F11: Significance F
A12: Regression | B12: 3 | C12: 1.4463599 | D12: 0.48211997 | E12: 42.195572 | F12: 1.346141e-08
A13: Residual | B13: 19 | C13: 0.21709102 | D13: 0.011425843
A14: Total | B14: 22 | C14: 1.6634509
B16: Coefficients | C16: Standard Error | D16: t Stat | E16: P-value | F16: Lower 95% | G16: Upper 95% | H16: Lower 95,0% | I16: Upper 95,0%
A17: Intercept | B17: 1.6749988 | C17: 0.081554435 | D17: 20.538414 | E17: 1.963848e-14 | F17: 1.5043034 | G17: 1.8456942 | H17: 1.5043034 | I17: 1.8456942
A18: dummy | B18: 0.20071872 | C18: 0.1288668 | D18: 1.5575673 | E18: 0.13583673 | F18: -0.069002604 | G18: 0.47044004 | H18: -0.069002604 | I18: 0.47044004
A19: duration | B19: 0.023596314 | C19: 0.0040200549 | D19: 5.8696496 | E19: 1.1854092e-05 | F19: 0.015182242 | G19: 0.032010385 | H19: 0.015182242 | I19: 0.032010385
A20: First week sales | B20: 0.0023406662 | C20: 0.00043050281 | D20: 5.4370521 | E20: 3.0236881e-05 | F20: 0.0014396135 | G20: 0.0032417189 | H20: 0.0014396135 | I20: 0.0032417189
A24: RESIDUAL OUTPUT | F24: PROBABILITY OUTPUT
A26: Observation | B26: Predicted log units | C26: Residuals | D26: Standard Residuals | F26: Percentile | G26: log units
A27: 1 | B27: 2.3882033 | C27: -0.1501572 | D27: -1.5115989 | F27: 2.173913 | G27: 2.1238516
A28: 2 | B28: 2.4233133 | C28: -0.13105723 | D28: -1.3193238 | F28: 6.5217391 | G28: 2.1303338
A29: 3 | B29: 2.3445541 | C29: -0.054519488 | D29: -0.54883549 | F29: 10.869565 | G29: 2.155336
A30: 4 | B30: 2.2700321 | C30: 0.052187211 | D30: 0.52535697 | F30: 15.217391 | G30: 2.1846914
A31: 5 | B31: 2.4686094 | C31: -0.0047164193 | D31: -0.047479138 | F31: 19.565217 | G31: 2.2148438
A32: 6 | B32: 2.2464358 | C32: -0.015986849 | D32: -0.16093603 | F32: 23.913043 | G32: 2.2304489
A33: 7 | B33: 2.4104721 | C33: -0.0090715157 | D33: -0.091320919 | F33: 28.26087 | G33: 2.2380461
A34: 8 | B34: 2.8071826 | C34: -0.091179212 | D34: -0.91788072 | F34: 32.608696 | G34: 2.2833012
A35: 9 | B35: 2.1996224 | C35: 0.015221402 | D35: 0.15323045 | F35: 36.956522 | G35: 2.2900346
A36: 10 | B36: 2.2183478 | C36: -0.088014007 | D36: -0.88601732 | F36: 41.304348 | G36: 2.2922561
A37: 11 | B37: 2.1902598 | C37: -0.0055683505 | D37: -0.056055338 | F37: 45.652174 | G37: 2.2966652
A38: 12 | B38: 2.3240571 | C38: 0.18379881 | D38: 1.8502615 | F38: 50 | G38: 2.3222193
... A49: 23 | B49: 2.3820048 | C49: 0.20345597 | D49: 2.0481457 | F49: 97.826087 | G49: 3.0948204

Sheet MultiLogRegr1stWeek
A1: SUMMARY OUTPUT
A3: Regression Statistics
A4: Multiple R | B4: 0.83720825
A5: R Square | B5: 0.70091765
A6: Adjusted R Square | B6: 0.65369413
A7: Standard Error | B7: 0.10330974
A8: Observations | B8: 23
A10: ANOVA
B11: df | C11: SS | D11: MS | E11: F | F11: Significance F
A12: Regression | B12: 3 | C12: 0.4752393 | D12: 0.1584131 | E12: 14.842552 | F12: 3.2308034e-05
A13: Residual | B13: 19 | C13: 0.20278514 | D13: 0.010672902
A14: Total | B14: 22 | C14: 0.67802444
B16: Coefficients | C16: Standard Error | D16: t Stat | E16: P-value | F16: Lower 95% | G16: Upper 95% | H16: Lower 95,0% | I16: Upper 95,0%
A17: Intercept | B17: -0.15180758 | C17: 0.37689488 | D17: -0.40278493 | E17: 0.69160245 | F17: -0.94065763 | G17: 0.63704248 | H17: -0.94065763 | I17: 0.63704248
A18: log units | B18: 1.0211167 | C18: 0.17391575 | D18: 5.8713295 | E18: 1.1811577e-05 | F18: 0.65710683 | G18: 1.3851265 | H18: 0.65710683 | I18: 1.3851265
A19: Days left | B19: -0.017757861 | C19: 0.0054051062 | D19: -3.2853861 | E19: 0.0038913284 | F19: -0.029070878 | G19: -0.0064448437 | H19: -0.029070878 | I19: -0.0064448437
A20: dummy | B20: -0.19930679 | C20: 0.097416833 | D20: -2.0459173 | E20: 0.054859785 | F20: -0.40320256 | G20: 0.0045889867 | H20: -0.40320256 | I20: 0.0045889867
A24: RESIDUAL OUTPUT | F24: PROBABILITY OUTPUT
A26: Observation | B26: Predicted Log 1st week | C26: Residuals | D26: Standard Residuals | F26: Percentile | G26: Log 1st week
A27: 1 | B27: 1.8848886 | C27: 0.083594375 | D27: 0.87070358 | F27: 2.173913 | G27: 1.6901961
A28: 2 | B28: 1.9402433 | C28: 0.093180479 | D28: 0.97055067 | F28: 6.5217391 | G28: 1.8976271
A29: 3 | B29: 2.0800378 | C29: 0.1102939 | D29: 1.1488009 | F29: 10.869565 | G29: 1.90309
A30: 4 | B30: 2.0773864 | C30: -0.064549165 | D30: -0.67233219 | F30: 15.217391 | G30: 1.9190781
A31: 5 | B31: 2.2575675 | C31: 0.060495851 | D31: 0.63011362 | F31: 19.565217 | G31: 1.9590414
A32: 6 | B32: 2.001436 | C32: 0.011401233 | D32: 0.11875314 | F32: 23.913043 | G32: 1.9684829
A33: 7 | B33: 2.1582397 | C33: 0.053947924 | D33: 0.56191162 | F33: 28.26087 | G33: 2.0128372
A34: 8 | B34: 2.3729387 | C34: 0.06163022 | D34: 0.641929 | F34: 32.608696 | G34: 2.0128372
A35: 9 | B35: 1.9855014 | C35: -0.066423298 | D35: -0.69185282 | F35: 36.956522 | G35: 2.0170333
A36: 10 | B36: 1.8992067 | C36: 0.059834653 | D36: 0.62322671 | F36: 41.304348 | G36: 2.0334238
A37: 11 | B37: 1.9547123 | C37: -0.057085163 | D37: -0.59458853 | F37: 45.652174 | G37: 2.0569049
A38: 12 | B38: 2.2491851 | C38: -0.18472714 | D38: -1.9240838 | F38: 50 | G38: 2.064458
... A49: 23 | B49: 2.1823955 | C49: 0.050600568 | D49: 0.52704617 | F49: 97.826087 | G49: 2.4345689

Sheet MultLogRegr1
A1: SUMMARY OUTPUT
A3: Regression Statistics
A4: Multiple R | B4: 0.81635932
A5: R Square | B5: 0.66644254 | D5: =10^(B17+B19*21) -> 315.50572
A6: Adjusted R Square | B6: 0.63308679
A7: Standard Error | B7: 0.16656177
A8: Observations | B8: 23
A10: ANOVA
B11: df | C11: SS | D11: MS | E11: F | F11: Significance F
A12: Regression | B12: 2 | C12: 1.1085945 | D12: 0.55429723 | E12: 19.979842 | F12: 1.7049302e-05
A13: Residual | B13: 20 | C13: 0.55485647 | D13: 0.027742824
A14: Total | B14: 22 | C14: 1.6634509
B16: Coefficients | C16: Standard Error | D16: t Stat | E16: P-value | F16: Lower 95% | G16: Upper 95% | H16: Lower 95,0% | I16: Upper 95,0%
A17: Intercept | B17: 1.8872482 | C17: 0.11157606 | D17: 16.914455 | E17: 2.5762331e-13 | F17: 1.6545046 | G17: 2.1199918 | H17: 1.6545046 | I17: 2.1199918
A18: X Variable 1 | B18: 0.18797378 | C18: 0.20077073 | D18: 0.93626085 | E18: 0.36030754 | F18: -0.23082663 | G18: 0.60677419 | H18: -0.23082663 | I18: 0.60677419
A19: X Variable 2 | B19: 0.029131384 | C19: 0.0060599796 | D19: 4.8071752 | E19: 0.0001072125 | F19: 0.016490488 | G19: 0.04177228 | H19: 0.016490488 | I19: 0.04177228
A23: RESIDUAL OUTPUT | F23: PROBABILITY OUTPUT
A25: Observation | B25: Predicted Y | C25: Residuals | D25: Standard Residuals | F25: Percentile | G25: Y
A26: 1 | B26: 2.4990072 | C26: -0.26096113 | D26: -1.6432242 | F26: 2.173913 | G26: 2.1238516
A27: 2 | B27: 2.4990072 | C27: -0.20675116 | D27: -1.301874 | F27: 6.5217391 | G27: 2.1303338
A28: 3 | B28: 2.2659562 | C28: 0.02407845 | D28: 0.15161757 | F28: 10.869565 | G28: 2.155336
A29: 4 | B29: 2.3242189 | C29: -0.0019996345 | D29: -0.012591331 | F29: 15.217391 | G29: 2.1846914
A30: 5 | B30: 2.2659562 | C30: 0.19793683 | D30: 1.2463718 | F30: 19.565217 | G30: 2.2148438
A31: 6 | B31: 2.2950875 | C31: -0.064638624 | D31: -0.40701753 | F31: 23.913043 | G31: 2.2304489
A32: 7 | B32: 2.3242189 | C32: 0.077181612 | D32: 0.48599842 | F32: 28.26087 | G32: 2.2380461
A33: 8 | B33: 2.4990072 | C33: 0.21699611 | D33: 1.3663846 | F33: 32.608696 | G33: 2.2833012
A34: 9 | B34: 2.2950875 | C34: -0.080243697 | D34: -0.50527981 | F34: 36.956522 | G34: 2.2900346
A35: 10 | B35: 2.2950875 | C35: -0.16475378 | D35: -1.0374242 | F35: 41.304348 | G35: 2.2922561
A36: 11 | B36: 2.2950875 | C36: -0.11039611 | D36: -0.69514404 | F36: 45.652174 | G36: 2.2966652
A37: 12 | B37: 2.3533503 | C37: 0.15450556 | D37: 0.97289309 | F37: 50 | G37: 2.3222193
... A48: 23 | B48: 2.2659562 | C48: 0.31950457 | D48: 2.0118615 | F48: 97.826087 | G48: 3.0948204
